Workbook

Sheet 報價單
A2: 新北市三重區三和路四段103號7樓 TEL: 02-22867899 FAX: 02-22869566
A3: {{工程名稱}} | C3: CLIENT 業主 : | F3: {{業主名稱}}
C4: PROJECT 工程名稱 : | F4: {{工程名稱}}
C5: LOCATION 工程地點： | F5: {{工程地點}}
C6: PROJECT NO 工程編號 : | F6: {{工程編號}}
A7: 項次 | B7: 名 稱 | C7: 單位 | D7: 數 量 | E7: 單 價 | F7: 總 價 | G7: 備 註 | I7: 單價 | J7: 總價 | K7: 毛利 | L7: 毛利率
A8: Item | B8: Description | C8: Unit | D8: Quantity | E8: Unit Price | F8: Amount | G8: Remarks
A9: 甲 | B9: 直接工程費
A10: 甲.壹 | B10: 假設工程 | C10: 式 | D10: 1 | E10: =F43 -> 78100 | F10: =E10*D10 -> 78100 | J10: =J43 -> 51100 | K10: =F10-J10 -> 27000 | L10: =K10/F10 -> 0.34571063
A11: 甲.貳 | B11: 拆除工程 | C11: 式 | D11: 1 | E11: =F51 -> 255000 | F11: =E11*D11 -> 255000 | J11: =J51 -> 175000 | K11: =F11-J11 -> 80000 | L11: =K11/F11 -> 0.31372549
A12: 甲.叁 | B12: 裝修工程 | C12: 式 | D12: 1 | E12: =F94 -> 2644560 | F12: =E12*D12 -> 2644560 | J12: =J94 -> 1758456.5 | K12: =F12-J12 -> 886103.5 | L12: =K12/F12 -> 0.33506651
A13: 甲.肆 | B13: 機電工程 | C13: 式 | D13: 1 | E13: =F108 -> 723100 | F13: =E13*D13 -> 723100 | J13: =J108 -> 322700 | K13: =F13-J13 -> 400400 | L13: =K13/F13 -> 0.55372701
A14: 甲.伍 | B14: 消防工程 | C14: 式 | D14: 1 | E14: =F135 -> 433850 | F14: =E14*D14 -> 433850 | J14: =J135 -> 380303 | K14: =F14-J14 -> 53547 | L14: =K14/F14 -> 0.12342284
A15: 甲.陸 | B15: 空調工程 | C15: 式 | D15: 1 | E15: =F152 -> 1215700 | F15: =E15*D15 -> 1215700 | J15: =J152 -> 456800 | K15: =F15-J15 -> 758900 | L15: =K15/F15 -> 0.6242494
B16: 直接工程費小計 | F16: =SUM(F10:F15) -> 5350310 | J16: =SUM(J10:J15) -> 3144359.5 | K16: =F16-J16 -> 2205950.5 | L16: =K16/F16 -> 0.41230331
A18: 乙 | B18: 間接工程費
A19: 乙.壹 | B19: 兩階段室內裝修審查跑照 | C19: 式 | D19: 1 | E19: 180000 | F19: =E19*D19 -> 180000 | H19: 1 | I19: 130000 | J19: =I19*H19 -> 130000 | K19: =F19-J19 -> 50000 | L19: =K19/F19 -> 0.27777778
A20: 乙.貳 | B20: 消防圖說審勘及其他作業 | C20: 式 | D20: 1 | E20: 100000 | F20: =E20*D20 -> 100000 | H20: 1 | I20: 125450 | J20: =I20*H20 -> 125450 | K20: =F20-J20 -> -25450 | L20: =K20/F20 -> -0.2545
A21: 乙.叁 | B21: 職業安全衛生管理及環境保護費 | C21: 式 | D21: 1 | E21: =ROUNDUP(F16*1.5%,0) -> 80255 | F21: =E21*D21 -> 80255
A22: 乙.肆 | B22: 品質管理費 | C22: 式 | D22: 1 | E22: =ROUNDUP(F16*1.5%,0) -> 80255 | F22: =E22*D22 -> 80255
A23: 乙.伍 | B23: 承商工程利潤管理費 | C23: 式 | D23: 1 | E23: =ROUNDUP(F16*7%,0) -> 374522 | F23: =E23*D23 -> 374522
A24: 乙.陸 | B24: 工程保險 | C24: 式 | D24: 1 | E24: =ROUNDUP(F16*0.5%,0) -> 26752 | F24: =E24*D24 -> 26752
B25: 間接工程費小計 | F25: =SUM(F19:F24) -> 841784
B26: 小計 | F26: =F25+F16 -> 6192094 | H26: =H28/1.05 -> 5238095.2 | J26: =SUM(J16:J25) -> 3399809.5 | K26: =H26-J26 -> 1838285.7 | L26: =K26/F26 -> 0.29687626
B27: 稅金 | F27: =ROUNDUP(F26*0.05,0) -> 309605
B28: 合計 | F28: =SUM(F26:F27) -> 6501699 | H28: 5500000
A38: 甲.壹. | B38: 假設工程 | I38: 單價 | J38: 總價 | K38: 毛利 | L38: 毛利率
A39: 甲.壹.一.1 | B39: 施工測量，工地放樣 | C39: 式 | D39: 1 | E39: 6500 | F39: =E39*D39 -> 6500 | H39: 1 | I39: 4500 | J39: =I39*H39 -> 4500 | K39: =F39-J39 -> 2000 | L39: =K39/F39 -> 0.30769231
A40: 甲.壹.一.2 | B40: 施工防護措施，施工圍籬 | C40: M | D40: 26 | E40: 1600 | F40: =E40*D40 -> 41600 | H40: 26 | I40: 1100 | J40: =I40*H40 -> 28600 | K40: =F40-J40 -> 13000 | L40: =K40/F40 -> 0.3125
A41: 甲.壹.一.3 | B41: 施工臨時水電設施及費用 | C41: 式 | D41: 1 | E41: 15000 | F41: =E41*D41 -> 15000 | H41: 1 | I41: 8000 | J41: =I41*H41 -> 8000 | K41: =F41-J41 -> 7000 | L41: =K41/F41 -> 0.46666667
A42: 甲.壹.一.4 | B42: 工區結構物及設施復原 | C42: 式 | D42: 1 | E42: 15000 | F42: =E42*D42 -> 15000 | H42: 1 | I42: 10000 | J42: =I42*H42 -> 10000 | K42: =F42-J42 -> 5000 | L42: =K42/F42 -> 0.33333333
B43: 假設工程小計 | F43: =SUM(F39:F42) -> 78100 | J43: =SUM(J39:J42) -> 51100 | K43: =F43-J43 -> 27000 | L43: =K43/F43 -> 0.34571063
A45: 甲.貳 | B45: 拆除工程
A46: 甲.貳.一.1 | B46: 既有/天花板/地板拆除 | C46: 式 | D46: 1 | E46: 95000 | F46: =E46*D46 -> 95000 | H46: 1 | I46: 65000 | J46: =I46*H46 -> 65000 | K46: =F46-J46 -> 30000 | L46: =K46/F46 -> 0.31578947
A47: 甲.貳.一.2 | B47: 既有隔間拆除 | C47: 式 | D47: 1 | E47: 48000 | F47: =E47*D47 -> 48000 | H47: 1 | I47: 35000 | J47: =I47*H47 -> 35000 | K47: =F47-J47 -> 13000 | L47: =K47/F47 -> 0.27083333
A48: 甲.貳.一.3 | B48: 既有水電/燈具/拆除 | C48: 式 | D48: 1 | E48: 15000 | F48: =E48*D48 -> 15000 | H48: 1 | I48: 9000 | J48: =I48*H48 -> 9000 | K48: =F48-J48 -> 6000 | L48: =K48/F48 -> 0.4
A49: 甲.貳.一.4 | B49: 既有出回風口拆除 | C49: 式 | D49: 1 | E49: 12000 | F49: =E49*D49 -> 12000 | H49: 1 | I49: 6000 | J49: =I49*H49 -> 6000 | K49: =F49-J49 -> 6000 | L49: =K49/F49 -> 0.5
A50: 甲.貳.一.5 | B50: 拆除廢棄物清運 | C50: 式 | D50: 1 | E50: 85000 | F50: =E50*D50 -> 85000 | H50: 4 | I50: 15000 | J50: =I50*H50 -> 60000 | K50: =F50-J50 -> 25000 | L50: =K50/F50 -> 0.29411765
B51: 拆除工程小計 | F51: =SUM(F46:F50) -> 255000 | J51: =SUM(J46:J50) -> 175000 | K51: =F51-J51 -> 80000 | L51: =K51/F51 -> 0.31372549
A53: 甲.叁 | B53: 裝修工程
...

Sheet 數量表
A1: 報價數量計算表
B2: 各室面積及周長 | D2: 明架矽酸鈣天花板 | E2: 單骨雙面輕隔間 | H2: 牆面美耐板 | K2: 牆面油漆 | N2: 上牆踢腳 | O2: 自平泥 | P2: PVC地磚 | U2: 防焰捲簾 | Y2: 防撞護角 | Z2: 系統櫃
A3: 項目 房間名稱 | B3: 面積/m² | C3: 周長cm | D3: 面積/m² | E3: 周長/cm | F3: 高度/cm | G3: 面積/m² | K3: 周長/cm | L3: 高度/cm | M3: 面積/m² | N3: 周長/cm | O3: 面積/m² | P3: 周長 | Q3: 高度 | R3: 上牆面積/m² | S3: 地面面積/m² | T3: 合計 | U3: 周長/cm | V3: 高度/cm | W3: 面積/m² | Y3: 支
A4: 7樓病房
A5: 醫師診間02 | B5: 8.7 | C5: 1179 | D5: =B5 -> 8.7 | E5: 783 | F5: 300 | G5: =ROUNDUP(E5*F5/10000,0) -> 24 | K5: =C5-283 -> 896 | L5: 300 | M5: =ROUNDUP(K5*L5/10000,0) -> 27 | N5: =C5 -> 1179 | O5: =B5 -> 8.7 | P5: =N5 -> 1179 | Q5: 10 | R5: =ROUNDUP(P5*Q5/10000,0) -> 2 | S5: =B5 -> 8.7 | T5: =S5+R5 -> 10.7 | U5: 283 | V5: 370 | W5: =ROUNDUP(U5*V5/900,0) -> 117
A6: 醫師診間01 | B6: 8.7 | C6: 1179 | D6: =B6 -> 8.7 | E6: 798 | F6: 300 | G6: =ROUNDUP(E6*F6/10000,0) -> 24 | K6: =C6 -> 1179 | L6: 300 | M6: =ROUNDUP(K6*L6/10000,0) -> 36 | N6: =C6 -> 1179 | O6: =B6 -> 8.7 | P6: =N6 -> 1179 | Q6: 10 | R6: =ROUNDUP(P6*Q6/10000,0) -> 2 | S6: =B6 -> 8.7 | T6: =S6+R6 -> 10.7
A7: 看診等候區 | B7: 20.3 | C7: 2174 | D7: =B7 -> 20.3 | E7: 2174 | F7: 495 | G7: =ROUNDUP(E7*F7/10000,0) -> 108 | H7: =K7 -> 2174 | I7: 120 | J7: =ROUNDUP(H7*I7/10000,0) -> 27 | K7: =C7 -> 2174 | L7: 300 | M7: =ROUNDUP(K7*L7/10000,0) -> 66 | N7: =C7 -> 2174 | O7: =B7 -> 20.3 | P7: =N7 -> 2174 | Q7: 10 | R7: =ROUNDUP(P7*Q7/10000,0) -> 3 | S7: =B7 -> 20.3 | T7: =S7+R7 -> 23.3 | U7: 186 | V7: 370 | W7: =ROUNDUP(U7*V7/900,0) -> 77
A8: 診療區 | B8: 25.3 | C8: =590+1195 -> 1785 | D8: =B8 -> 25.3 | E8: 2013 | F8: 300 | G8: =ROUNDUP(E8*F8/10000,0) -> 61 | H8: =K8 -> 1320 | I8: 120 | J8: =ROUNDUP(H8*I8/10000,0) -> 16 | K8: =C8-288-177 -> 1320 | L8: 300 | M8: =ROUNDUP(K8*L8/10000,0) -> 40 | N8: =C8 -> 1785 | O8: =B8 -> 25.3 | P8: =N8 -> 1785 | Q8: 10 | R8: =ROUNDUP(P8*Q8/10000,0) -> 2 | S8: =B8 -> 25.3 | T8: =S8+R8 -> 27.3 | U8: =321+177 -> 498 | V8: 370 | W8: =ROUNDUP(U8*V8/900,0) -> 205
A9: 批價櫃檯 | B9: 2.4 | C9: 620 | D9: =B9 -> 2.4 | E9: 1036 | F9: 300 | G9: =ROUNDUP(E9*F9/10000,0) -> 32 | K9: =C9 -> 620 | L9: 300 | M9: =ROUNDUP(K9*L9/10000,0) -> 19 | N9: =C9 -> 620 | O9: =B9 -> 2.4 | P9: =N9 -> 620 | Q9: 10 | R9: =ROUNDUP(P9*Q9/10000,0) -> 1 | S9: =B9 -> 2.4 | T9: =S9+R9 -> 3.4 | V9: 370 | W9: =ROUNDUP(U9*V9/900,0) -> 0
A10: 中醫藥局 | B10: 21.3 | C10: 2715 | D10: =B10 -> 21.3 | E10: =1033+323 -> 1356 | F10: 495 | G10: =ROUNDUP(E10*F10/10000,0) -> 68 | K10: =C10 -> 2715 | L10: 300 | M10: =ROUNDUP(K10*L10/10000,0) -> 82 | N10: =C10 -> 2715 | O10: =B10 -> 21.3 | P10: =N10 -> 2715 | Q10: 10 | R10: =ROUNDUP(P10*Q10/10000,0) -> 3 | S10: =B10 -> 21.3 | T10: =S10+R10 -> 24.3 | V10: 370 | W10: =ROUNDUP(U10*V10/900,0) -> 0
A11: 中醫庫房 | B11: 4.6 | C11: 892 | D11: =B11 -> 4.6 | E11: 195 | F11: 300 | G11: 8 | K11: =C11-131 -> 761 | L11: 300 | M11: =ROUNDUP(K11*L11/10000,0) -> 23 | N11: =C11 -> 892 | O11: =B11 -> 4.6 | P11: =N11 -> 892 | Q11: 10 | R11: =ROUNDUP(P11*Q11/10000,0) -> 1 | S11: =B11 -> 4.6 | T11: =S11+R11 -> 5.6 | U11: 132 | V11: 370 | W11: =ROUNDUP(U11*V11/900,0) -> 55
A12: 藥局庫房 | B12: 19.4 | C12: 1866 | D12: =B12 -> 19.4 | E12: =228+ 457 -> 685 | F12: 495 | G12: =ROUNDUP(E12*F12/10000,0) -> 34 | K12: =C12-370 -> 1496 | L12: 300 | M12: =ROUNDUP(K12*L12/10000,0) -> 45 | N12: =C12 -> 1866 | O12: =B12 -> 19.4 | P12: =N12 -> 1866 | Q12: 10 | R12: =ROUNDUP(P12*Q12/10000,0) -> 2 | S12: =B12 -> 19.4 | T12: =S12+R12 -> 21.4
A13: 外部等候區
A14: 加總 | B14: =SUM(B5:B12) -> 110.7 | C14: =SUM(C5:C12) -> 12410 | D14: =SUM(D5:D12) -> 110.7 | G14: =SUM(G5:G12) -> 359 | J14: =SUM(J5:J13) -> 43 | M14: =SUM(M5:M12) -> 338 | N14: =SUM(N5:N12)/100 -> 124.1 | O14: =SUM(O5:O12) -> 110.7 | S14: =SUM(S5:S12) -> 110.7 | T14: =SUM(T5:T12) -> 126.7 | W14: =SUM(W5:W12) -> 454
M16: 廠商數量計算
B17: 各室面積及周長 | D17: 明架矽酸鈣天花板 | E17: 單骨雙面輕隔間 | H17: 牆面美耐板 | K17: 牆面油漆 | N17: 上牆踢腳 | O17: 自平泥 | P17: PVC地磚 | U17: 防焰捲簾 | Y17: 防撞護角 | Z17: 系統櫃
A18: 項目 房間名稱 | B18: 面積/m² | C18: 周長cm | D18: 面積/m² | E18: 周長/cm | F18: 高度/cm | G18: 面積/m² | K18: 周長/cm | L18: 高度/cm | M18: 面積/m² | N18: 周長/cm | O18: 面積/m² | P18: 周長 | Q18: 高度 | R18: 上牆面積/m² | S18: 地面面積/m² | T18: 合計 | U18: 周長/cm | V18: 高度/cm | W18: 面積/m² | Y18: 支
A19: 7樓病房
A20: 醫師診間02 | B20: 8.7 | C20: 1179 | D20: =B20 -> 8.7 | E20: 578 | F20: 280 | G20: =ROUNDUP(E20*F20/10000,0) -> 17 | K20: =C20-283 -> 896 | L20: 370 | M20: =ROUNDUP(K20*L20/10000,0) -> 34 | N20: =C20 -> 1179 | O20: =B20 -> 8.7 | P20: =N20 -> 1179 | Q20: 10 | R20: =ROUNDUP(P20*Q20/10000,0) -> 2 | S20: =B20 -> 8.7 | T20: =S20+R20 -> 10.7 | U20: 283 | V20: 370 | W20: =ROUNDUP(U20*V20/900,0) -> 117
A21: 醫師診間01 | B21: 8.7 | C21: 1179 | D21: =B21 -> 8.7 | E21: 592 | F21: 280 | G21: =ROUNDUP(E21*F21/10000,0) -> 17 | K21: =C21 -> 1179 | L21: 370 | M21: =ROUNDUP(K21*L21/10000,0) -> 44 | N21: =C21 -> 1179 | O21: =B21 -> 8.7 | P21: =N21 -> 1179 | Q21: 10 | R21: =ROUNDUP(P21*Q21/10000,0) -> 2 | S21: =B21 -> 8.7 | T21: =S21+R21 -> 10.7
A22: 看診等候區 | B22: 20.3 | C22: 2104 | D22: =B22 -> 20.3 | E22: 2084 | F22: 495 | G22: =ROUNDUP(E22*F22/10000,0) -> 104 | H22: =K22 -> 1904 | I22: 110 | J22: =ROUNDUP(H22*I22/10000,0) -> 21 | K22: =C22-200 -> 1904 | L22: 370 | M22: =ROUNDUP(K22*L22/10000,0) -> 71 | N22: =C22 -> 2104 | O22: =B22 -> 20.3 | P22: =N22 -> 2104 | Q22: 10 | R22: =ROUNDUP(P22*Q22/10000,0) -> 3 | S22: =B22 -> 20.3 | T22: =S22+R22 -> 23.3 | U22: 186 | V22: 370 | W22: =ROUNDUP(U22*V22/900,0) -> 77
A23: 診療區 | B23: 25.3 | C23: 2183 | D23: =B23 -> 25.3 | F23: 280 | G23: =ROUNDUP(E23*F23/10000,0) -> 0 | H23: =K23 -> 1718 | I23: 110 | J23: =ROUNDUP(H23*I23/10000,0) -> 19 | K23: =C23-288-177 -> 1718 | L23: 370 | M23: =ROUNDUP(K23*L23/10000,0) -> 64 | N23: =C23 -> 2183 | O23: =B23 -> 25.3 | P23: =N23 -> 2183 | Q23: 10 | R23: =ROUNDUP(P23*Q23/10000,0) -> 3 | S23: =B23 -> 25.3 | T23: =S23+R23 -> 28.3 | U23: =321+177 -> 498 | V23: 370 | W23: =ROUNDUP(U23*V23/900,0) -> 205
A24: 批價櫃檯 | B24: 2.4 | C24: 620 | D24: =B24 -> 2.4 | E24: =546+90 -> 636 | F24: 280 | G24: =ROUNDUP(E24*F24/10000,0) -> 18 | K24: =C24 -> 620 | L24: 370 | M24: =ROUNDUP(K24*L24/10000,0) -> 23 | N24: =C24 -> 620 | O24: =B24 -> 2.4 | P24: =N24 -> 620 | Q24: 10 | R24: =ROUNDUP(P24*Q24/10000,0) -> 1 | S24: =B24 -> 2.4 | T24: =S24+R24 -> 3.4 | V24: 370 | W24: =ROUNDUP(U24*V24/900,0) -> 0
A25: 中醫藥局 | B25: 21.3 | C25: 2715 | D25: =B25 -> 21.3 | E25: 1521 | F25: 280 | G25: =ROUNDUP(E25*F25/10000,0) -> 43 | K25: =C25 -> 2715 | L25: 370 | M25: =ROUNDUP(K25*L25/10000,0) -> 101 | N25: =C25 -> 2715 | O25: =B25 -> 21.3 | P25: =N25 -> 2715 | Q25: 10 | R25: =ROUNDUP(P25*Q25/10000,0) -> 3 | S25: =B25 -> 21.3 | T25: =S25+R25 -> 24.3 | V25: 370 | W25: =ROUNDUP(U25*V25/900,0) -> 0
A26: 中醫庫房 | B26: 4.6 | C26: 892 | D26: =B26 -> 4.6 | E26: 112 | F26: 280 | G26: =ROUNDUP(E26*F26/10000,0) -> 4 | K26: =C26-131 -> 761 | L26: 370 | M26: =ROUNDUP(K26*L26/10000,0) -> 29 | N26: =C26 -> 892 | O26: =B26 -> 4.6 | P26: =N26 -> 892 | Q26: 10 | R26: =ROUNDUP(P26*Q26/10000,0) -> 1 | S26: =B26 -> 4.6 | T26: =S26+R26 -> 5.6 | U26: 132 | V26: 370 | W26: =ROUNDUP(U26*V26/900,0) -> 55
A27: 藥局庫房 | B27: 19.4 | C27: 1866 | D27: =B27 -> 19.4 | E27: 491 | F27: 495 | G27: =ROUNDUP(E27*F27/10000,0) -> 25 | K27: =C27-370 -> 1496 | L27: 370 | M27: =ROUNDUP(K27*L27/10000,0) -> 56 | N27: =C27 -> 1866 | O27: =B27 -> 19.4 | P27: =N27 -> 1866 | Q27: 10 | R27: =ROUNDUP(P27*Q27/10000,0) -> 2 | S27: =B27 -> 19.4 | T27: =S27+R27 -> 21.4
A28: 外部等候區 | H28: 1447 | I28: 110 | J28: =ROUNDUP(H28*I28/10000,0) -> 16
A29: 加總 | B29: =SUM(B20:B27) -> 110.7 | C29: =SUM(C20:C27) -> 12738 | D29: =SUM(D20:D27) -> 110.7 | G29: =SUM(G20:G27) -> 228 | J29: =SUM(J20:J28) -> 56 | M29: =SUM(M20:M27) -> 422 | N29: =SUM(N20:N27)/100 -> 127.38 | O29: =SUM(O20:O27) -> 110.7 | S29: =SUM(S20:S27) -> 110.7 | T29: =SUM(T20:T27) -> 127.7 | W29: =SUM(W20:W27) -> 454

Sheet 機電空白標單
A2: 新北市三重區三和路四段103號7樓 TEL: 02-22867899 FAX: 02-22869566
A3: {{工程名稱}}機電工程標單 | C3: CLIENT 業主 : | F3: {{業主名稱}}
C4: PROJECT 工程名稱 : | F4: {{工程名稱}}
C5: LOCATION 工程地點： | F5: {{工程地點}}
C6: PROJECT NO 工程編號 : | F6: {{工程編號}}
A7: 項次 | B7: 名 稱 | C7: 單位 | D7: 數 量 | E7: 單 價 | F7: 總 價 | G7: 備 註 | I7: 單價 | J7: 總價 | K7: 毛利 | L7: 毛利率
A8: Item | B8: Description | C8: Unit | D8: Quantity | E8: Unit Price | F8: Amount | G8: Remarks
A9: 甲.肆 | B9: 機電工程
A10: 甲.肆.1 | B10: 110V/220V電源盤配線安裝 | C10: 組 | D10: 2 | G10: 含配電盤 | H10: 2 | J10: =I10*H10 -> 0 | K10: =F10-J10 -> 0 | L10: =K10/F10 -> #DIV/0!
A11: 甲.肆.2 | B11: 燈具插座電源迴路 | C11: 回 | D11: 11 | H11: 11 | J11: =I11*H11 -> 0 | K11: =F11-J11 -> 0 | L11: =K11/F11 -> #DIV/0!
A12: 甲.肆.3 | B12: 空調電源迴路 | C12: 回 | D12: 3 | H12: 3 | J12: =I12*H12 -> 0 | K12: =F12-J12 -> 0 | L12: =K12/F12 -> #DIV/0!
A13: 甲.肆.4 | B13: LED平板燈配置 | C13: 盞 | D13: 36 | G13: 含燈具 | H13: 36 | J13: =I13*H13 -> 0 | K13: =F13-J13 -> 0 | L13: =K13/F13 -> #DIV/0!
A14: 甲.肆.5 | B14: 調光崁燈 | C14: 盞 | D14: 5 | G14: 含燈具 | H14: 3 | J14: =I14*H14 -> 0 | K14: =F14-J14 -> 0 | L14: =K14/F14 -> #DIV/0!
A15: 甲.肆.6 | B15: 開關配置 | C15: 式 | D15: 1 | H15: 1 | J15: =I15*H15 -> 0 | K15: =F16-J15 -> 0 | L15: =K15/F16 -> #DIV/0!
A16: 甲.肆.7 | B16: 資訊電信配線安裝 | C16: 式 | D16: 1 | H16: 1 | J16: =I16*H16 -> 0 | K16: =F17-J16 -> 0 | L16: =K16/F17 -> #DIV/0!
A17: 甲.肆.8 | B17: 110V插座配置 | C17: 式 | D17: 1 | H17: 1 | J17: =I17*H17 -> 0 | K17: =F18-J17 -> 0 | L17: =K17/F18 -> #DIV/0!
A18: 甲.肆.9 | B18: 水槽給水/排水配管 | C18: 式 | D18: 1
A19: 甲.肆.10 | B19: 水槽感應式龍頭 | C19: 組 | D19: 1 | G19: 凱薩、HCG或同等品
J36: =SUM(J10:J17) -> 0 | K36: =F37-J36 -> 0 | L36: =K36/F37 -> #DIV/0!
B37: 機電工程小計 | F37: =SUM(F10:F18) -> 0
