Workbook

Sheet 總表
A2: 國立臺灣大學醫學院附設醫院
A4: 總表[標單]
M6: 115年6月15日
M8: 第 1 頁 共 1 頁
A10: 工程名稱 | D10: 西址六東1樓(6E1)內科加護病房暨特殊病原科技照護 示範中心整修工程 | I10: 會計科目
A11: 施工地點 | D11: 臺北市 | I11: 工程編號 | L11: FB24033360_V6
A12: 項 次 | D12: 工 作 項 目 | L12: 金額(元) | N12: 備註
A13: 壹 | D13: 建築裝修工程 | L13: =IF(ISNUMBER(詳細表!N13),詳細表!N13,"-") -> -
A14: 貳 | D14: 水電設備工程 | L14: =IF(ISNUMBER(詳細表!N404),詳細表!N404,"-") -> -
A15: 參 | D15: 消防設備工程 | L15: =IF(ISNUMBER(詳細表!N1554),詳細表!N1554,"-") -> -
A16: 肆 | D16: 空調設備工程 | L16: =IF(ISNUMBER(詳細表!N1673),詳細表!N1673,"-") -> -
A17: 伍 | D17: 醫療氣體設備工程 | L17: =IF(ISNUMBER(詳細表!N2580),詳細表!N2580,"-") -> -
A18: 陸 | D18: RO處理系統 | L18: =IF(ISNUMBER(詳細表!N2635),詳細表!N2635,"-") -> -
D19: 直接工程費 小計(A) | L19: =IF(COUNT(L13,L14,L15,L16,L17,L18)=6,SUM(L13,L14,L15,L16,L17,L18),"-") -> -
A20: 柒 | D20: 職業安全衛生管理費，(A*0.8%) | L20: =IF(ISNUMBER(L19),ROUND(L19*0.008,0),"-") -> -
A21: 捌 | D21: 工程品質管理費及試驗費，(A*1.0%) | L21: =IF(ISNUMBER(L19),ROUND(L19*0.01,0),"-") -> -
A22: 玖 | D22: 環境維護費，(A*0.3%) | L22: =IF(ISNUMBER(L19),ROUND(L19*0.003,0),"-") -> -
A23: 拾 | D23: 承包商管理費及利潤，(A*6.0%) | L23: =IF(ISNUMBER(L19),ROUND(L19*0.06,0),"-") -> -
A24: 拾壹 | D24: 保險費，(A*0.18%) | L24: =IF(ISNUMBER(L19),ROUND(L19*0.0018,0),"-") -> -
D25: 間接工程費 小計(B) | L25: =IF(COUNT(L20,L21,L22,L23,L24)=5,SUM(L20,L21,L22,L23,L24),"-") -> -
A26: 拾貳 | D26: 營業稅(C=(A+B)*5%) | L26: =IF(COUNT(L19,L25)=2,ROUND(SUM(L19,L25)*0.05,0),"-") -> -
D27: 總價(總計) | L27: =IF(COUNT(L19,L25,L26)=3,SUM(L19,L25,L26),"-") -> -
B44: 投標廠商： | E44: [印] | G44: 負責人： | J44: [印]

Sheet 詳細表
A2: 國立臺灣大學醫學院附設醫院
A4: 詳細價目表[標單]
O6: 115年6月15日
O8: 第 1 頁 共 93 頁
A10: 工程名稱 | C10: 西址六東1樓(6E1)內科加護病房暨特殊病原科技照護示範中心整 修工程 | M10: 會計科目
A11: 施工地點 | C11: 臺北市 | M11: 工程編號 | N11: FB24033360_V6
A12: 項 次 | C12: 項 目 及 說 明 | H12: 單 位 | J12: 數 量 | M12: 單 價 | N12: 複 價 | P12: 編碼(備註)
A13: 壹 | C13: 建築裝修工程 | J13: 1 | M13: =IF(COUNT(N13,J13)=2,IF(J13=0,"-",N13/J13),"-") -> - | N13: =IF(COUNT(N14,N40,N47,N68,N75,N98,N123,N241,N364,N372)=10,SUM(N14,N40,N47,N68,N75,N98,N123,N241,N364,N372),"-") -> -
A14: 壹.一 | C14: 假設工程 | J14: 1 | M14: =IF(COUNT(N14,J14)=2,IF(J14=0,"-",N14/J14),"-") -> - | N14: =IF(COUNT(N15,N16,N17,N18,N19,N20,N21,N22,N23)=9,SUM(N15,N16,N17,N18,N19,N20,N21,N22,N23),"-") -> -
A15: 壹.一.1 | C15: 施工圍籬，室內圍籬(6分麗光板)，含拆裝 | H15: M2 | J15: 59.5 | M15: =IF(ISNUMBER(單價分析!T28),單價分析!T28,"") | N15: =IF(COUNT(J15,M15)=2,ROUND(J15*M15,0),"- -") -> - - | P15: 0156400002ZBICU 01,*
A16: 壹.一.2 | C16: 施工圍籬，室外圍籬，高度2.4M，含拆裝 | H16: M2 | J16: 487 | M16: =IF(ISNUMBER(單價分析!T41),單價分析!T41,"") | N16: =IF(COUNT(J16,M16)=2,ROUND(J16*M16,0),"- -") -> - - | P16: 0156400002ZBICU 02,*
A17: 壹.一.3 | C17: 公共管線系統之保護，就地保護，運貨電 梯及進料動線施工保護工程 | H17: 式 | J17: 1 | N17: =IF(COUNT(J17,M17)=2,ROUND(J17*M17,0),"- - -") -> - - - | P17: 0225200004ZPS00 2,管線及設備拆 除前管線調查
A18: 壹.一.4 | C18: 工程告示牌，及工地標誌，工程告示牌， 鋁質 | H18: 式 | J18: 1 | M18: =IF(ISNUMBER(單價分析!T72),單價分析!T72,"") | N18: =IF(COUNT(J18,M18)=2,ROUND(J18*M18,0),"- -") -> - - | P18: 015831000BZPS00 3,*
A19: 壹.一.5 | C19: 施工輔助設施，施工架及高空作業設備 | H19: 式 | J19: 1 | N19: =IF(COUNT(J19,M19)=2,ROUND(J19*M19,0),"- -") -> - - | P19: 0154010004ZG010 1
A20: 壹.一.6 | C20: 產品，施工測量，工地放樣，平面測量 | H20: M2 | J20: 555.6 | M20: =IF(ISNUMBER(單價分析!T87),單價分析!T87,"") | N20: =IF(COUNT(J20,M20)=2,ROUND(J20*M20,0),"- - - - - -") -> - - - - - - | P20: M0172551002ZPS0 05,面及高程測量 、機電定位測量 ，含放樣、水平 測量調查(高程校 準),*
A21: 壹.一.7 | C21: 工地清理，施工環境維護費及完工後細清 費用(含竣工驗收後地板打蠟) | H21: 式 | J21: 1 | N21: =IF(COUNT(J21,M21)=2,ROUND(J21*M21,0),"- - - - - - - -") -> - - - - - - - - | P21: 0174010004ZG010 2,包含施工中醫 療感控防護措施 、工區集塵設備 及集塵墊、施工 中工區消防防護 措施、工區臨時 安全配電設備
A22: 壹.一.8 | C22: 臨時設施，(工區臨時施工設備、零星工項 及雜費) | H22: 式 | J22: 1 | N22: =IF(COUNT(J22,M22)=2,ROUND(J22*M22,0),"- -") -> - - | P22: 0151000004ZPS00 1
A23: 壹.一.9 | C23: 資料送審，各式計畫書，施工圖及竣工圖 | H23: 式 | J23: 1 | N23: =IF(COUNT(J23,M23)=2,ROUND(J23*M23,0),"-") -> - | P23: 01330B0004ZBICU
B25: 投標廠商： | E25: [印] | G25: 負責人： | K25: [印]
A28: 國立臺灣大學醫學院附設醫院
A30: 詳細價目表[標單]
O32: 115年6月15日
O34: 第 2 頁 共 93 頁
A36: 工程名稱 | C36: 西址六東1樓(6E1)內科加護病房暨特殊病原科技照護示範中心整 修工程 | M36: 會計科目
A37: 施工地點 | C37: 臺北市 | M37: 工程編號 | N37: FB24033360_V6
A38: 項 次 | C38: 項 目 及 說 明 | H38: 單 位 | J38: 數 量 | M38: 單 價 | N38: 複 價 | P38: 編碼(備註)
C39: 繪製、各類材料送審及實際樣品製作(含相 關電子檔)以及辦理工程施工期間攝影、拍 照及室內裝修竣工查驗作業 | N39: - - - | P39: 01
A40: 壹.二 | C40: 拆除暨運棄工程 | J40: 1 | M40: =IF(COUNT(N40,J40)=2,IF(J40=0,"-",N40/J40),"-") -> - | N40: =IF(COUNT(N41,N42,N43,N44,N45,N46)=6,SUM(N41,N42,N43,N44,N45,N46),"-") -> -
A41: 壹.二.1 | C41: 工地拆除，拆除前清查管線、列冊拆除內 容及須保留管線、設備現場標示 | H41: 式 | J41: 1 | N41: =IF(COUNT(J41,M41)=2,ROUND(J41*M41,0),"- -") -> - - | P41: 0222000004ZG050 1
A42: 壹.二.2 | C42: 工地拆除，室內既有 RC/ 磚石隔間牆、地 坪煤渣砂漿層、牆面 樑 柱及天花底板粉 刷層打除、外牆窗戶、各類，既有空調設 備、風管、風口拆除，既有空調管路與排 水拆除，既有空調配電與配電管拆除(包含 既有配電盤拆除)。 | H42: 式 | J42: 1 | N42: =IF(COUNT(J42,M42)=2,ROUND(J42*M42,0),"- - - - - -") -> - - - - - - | P42: 0222000004ZBICU 03
A43: 壹.二.3 | C43: 工地拆除，拆除後既有構體修補填塞及復 原費（含外牆防水漆復原） | H43: 式 | J43: 1 | N43: =IF(COUNT(J43,M43)=2,ROUND(J43*M43,0),"- -") -> - - | P43: 0222000004ZBICU 04
A44: 壹.二.4 | C44: 交換機室MDF線架搬遷及內線拆除及保留專 用迴路 | H44: 式 | J44: 1 | N44: =IF(COUNT(J44,M44)=2,ROUND(J44*M44,0),"- -") -> - - | P44: 0222000004ZG051 1
A45: 壹.二.5 | C45: 違章拆除(天花板、隔間牆拆除清運)+屋頂 結構拆除 | H45: 式 | J45: 1 | N45: =IF(COUNT(J45,M45)=2,ROUND(J45*M45,0),"- -") -> - - | P45: 0222000004ZG051 2
A46: 壹.二.6 | C46: 運雜費，全案工程的廢棄物清除運棄處理 費用，(含廢棄物運棄及處理費、開立合法 棄置證明) | H46: 式 | J46: 1 | N46: =IF(COUNT(J46,M46)=2,ROUND(J46*M46,0),"- - -") -> - - - | P46: 012713000409ZBI CU01
A47: 壹.三 | C47: 天花工程 | J47: 1 | M47: =IF(COUNT(N47,J47)=2,IF(J47=0,"-",N47/J47),"-") -> - | N47: =IF(COUNT(N48,N49,N50,N51,N67)=5,SUM(N48,N49,N50,N51,N67),"-") -> -
A48: 壹.三.1 | C48: 天花板，庫板天花 (耐燃一級) | H48: M2 | J48: 333 | M48: =IF(ISNUMBER(單價分析!T117),單價分析!T117,"") | N48: =IF(COUNT(J48,M48)=2,ROUND(J48*M48,0),"- -") -> - - | P48: 0950000002ZG050 5,*
A49: 壹.三.2 | C49: 天花板，明架，低落塵礦纖天花板(耐燃一 級)，15mmTH ，60*60cm | H49: M2 | J49: 260 | M49: =IF(ISNUMBER(單價分析!T129),單價分析!T129,"") | N49: =IF(COUNT(J49,M49)=2,ROUND(J49*M49,0),"- -") -> - - | P49: 0950000002ZG050 1,*
A50: 壹.三.3 | C50: 天花板，明架，防潮矽酸鈣(耐燃一級)， 6mmTH，60*60cm | H50: M2 | J50: 62 | M50: =IF(ISNUMBER(單價分析!T159),單價分析!T159,"") | N50: =IF(COUNT(J50,M50)=2,ROUND(J50*M50,0),"- -") -> - - | P50: 0950000002ZG050 3,*
A51: 壹.三.4 | C51: 天花板，暗架庫板天花，下掀式氣密式檢 修孔60*60開孔 | H51: 組 | J51: 24 | N51: =IF(COUNT(J51,M51)=2,ROUND(J51*M51,0),"- -") -> - - | P51: 0950000008ZBICU 01
B53: 投標廠商： | E53: [印] | G53: 負責人： | K53: [印]
...

Sheet 單價分析
A2: 國立臺灣大學醫學院附設醫院
A4: 單價分析表[標單]
F6: 工程名稱：西址六東1樓(6E1)內科加護病房暨特殊病原科技照護示範中心整修工
F8: 程
U9: 115年6月15日
U12: 第 1 頁 共 103 頁
B13: 項次： | F13: 工程編號：FB24033360_V6
A16: 壹.一.1 | E16: 工作項目：施工圍籬，室內圍籬(6分麗光板)，含拆裝 | N16: 單位：M2 | T16: 計 價 代 碼 ： 0156400002ZBICU01
E17: 工料名稱 | L17: 單位 | N17: 數量 | P17: 單價 | T17: 複價 | V17: 編碼(備註)
E18: 產品，木材，6分麗光板 | L18: M2 | N18: 1 | T18: =IF(COUNT(N18,P18)=2,ROUND(N18*P18,2),"- -") -> - - | V18: M0606000002ZBIC U01
E19: 產品，木材，固定角材 | L19: 式 | N19: 1 | T19: =IF(COUNT(N19,P19)=2,ROUND(N19*P19,2),"- -") -> - - | V19: M0606000004ZBIC U01
E20: 施工費 | L20: 式 | N20: 1 | T20: =IF(COUNT(N20,P20)=2,ROUND(N20*P20,2),"-") -> - | V20: 0127180004
E21: 零星工料，約以上項目之2.0% | L21: 式 | N21: 1 | P21: =IF(COUNT(T18,T19,T20)=3,ROUND(SUM(T18,T19,T20)*0.02,2),"") | T21: =IF(COUNT(N21,P21)=2,ROUND(N21*P21,2),"-") -> - | V21: W0127114004
E22: 合計 | L22: M2 | N22: 1 | T22: =IF(COUNT(T18,T19,T20,T21)=4,SUM(T18,T19,T20,T21),"-") -> -
E28: 人工： 機具： 材料： 雜項： | N28: 每 M2 單價計 | T28: =IF(COUNT(T22,N22)=2,IF(N22=0,"-",ROUND(T22/N22,2)),"-") -> -
A29: 壹.一.2 | E29: 工作項目：施工圍籬，室外圍籬，高度2.4M，含拆裝 | N29: 單位：M2 | T29: 計 價 代 碼 ： 0156400002ZBICU02
E30: 工料名稱 | L30: 單位 | N30: 數量 | P30: 單價 | T30: 複價 | V30: 編碼(備註)
E31: 產品，施工圍籬，烤漆鋼板 | L31: M2 | N31: 1 | T31: =IF(COUNT(N31,P31)=2,ROUND(N31*P31,2),"- -") -> - - | V31: M0156400002ZBIC U01
E32: 產品，施工圍籬，固定角鋼材料 | L32: 式 | N32: 1 | T32: =IF(COUNT(N32,P32)=2,ROUND(N32*P32,2),"- -") -> - - | V32: M0156400004ZBIC U01
E33: 施工費 | L33: 式 | N33: 1 | T33: =IF(COUNT(N33,P33)=2,ROUND(N33*P33,2),"-") -> - | V33: 0127180004
E34: 零星工料，約以上項目之2.0% | L34: 式 | N34: 1 | P34: =IF(COUNT(T31,T32,T33)=3,ROUND(SUM(T31,T32,T33)*0.02,2),"") | T34: =IF(COUNT(N34,P34)=2,ROUND(N34*P34,2),"-") -> - | V34: W0127114004
E35: 合計 | L35: M2 | N35: 1 | T35: =IF(COUNT(T31,T32,T33,T34)=4,SUM(T31,T32,T33,T34),"-") -> -
E41: 人工： 機具： 材料： 雜項： | N41: 每 M2 單價計 | T41: =IF(COUNT(T35,N35)=2,IF(N35=0,"-",ROUND(T35/N35,2)),"-") -> -
C43: 投標廠商： | I43: [印] | M43: 負責人： | Q43: [印]
A46: 國立臺灣大學醫學院附設醫院
A48: 單價分析表[標單]
F50: 工程名稱：西址六東1樓(6E1)內科加護病房暨特殊病原科技照護示範中心整修工
F52: 程
U53: 115年6月15日
U56: 第 2 頁 共 103 頁
B57: 項次： | F57: 工程編號：FB24033360_V6
A60: 壹.一.4 | E60: 工作項目：工程告示牌，及工地標誌，工程告示牌，鋁質 | N60: 單位：式 | T60: 計 價 代 碼 ： 015831000BZPS003
E61: 工料名稱 | L61: 單位 | N61: 數量 | P61: 單價 | T61: 複價 | V61: 編碼(備註)
E62: 產品，工程告示牌及工地標誌，工程告示牌， 鋁質，長300x寬170cm | L62: 面 | N62: 1 | T62: =IF(COUNT(N62,P62)=2,ROUND(N62*P62,2),"- -") -> - - | V62: M015831120A
E63: 產品，工程告示牌及工地標誌，工程告示牌， 鍍鋅角鋼，裝拆及維護 | L63: 式 | N63: 1 | T63: =IF(COUNT(N63,P63)=2,ROUND(N63*P63,2),"- -") -> - - | V63: M0158316044
E64: 施工費 | L64: 式 | N64: 1 | T64: =IF(COUNT(N64,P64)=2,ROUND(N64*P64,2),"-") -> - | V64: 0127180004
E65: 零星工料，約以上項目之2.0% | L65: 式 | N65: 1 | P65: =IF(COUNT(T62,T63,T64)=3,ROUND(SUM(T62,T63,T64)*0.02,2),"") | T65: =IF(COUNT(N65,P65)=2,ROUND(N65*P65,2),"-") -> - | V65: W0127114004
E66: 合計 | L66: 式 | N66: 1 | T66: =IF(COUNT(T62,T63,T64,T65)=4,SUM(T62,T63,T64,T65),"-") -> -
E72: 人工： 機具： 材料： 雜項： | N72: 每 式 單價計 | T72: =IF(COUNT(T66,N66)=2,IF(N66=0,"-",ROUND(T66/N66,2)),"-") -> -
A73: 壹.一.6 | E73: 工作項目：產品，施工測量，工地放樣，平面測量 | N73: 單位：M2 | T73: 計 價 代 碼 ： M0172551002ZPS005
...

Sheet 資源統計
A2: 國立臺灣大學醫學院附設醫院
A4: 資源統計表[標單]
B6: 工 程 編 號 FB24033360_V6
B8: 工 程 名 稱 西址六東1樓(6E1)內科加護病房暨特殊病原科技照護示範中心整修工程
R9: 單位﹝元﹞
U10: 第 1 頁 共 37 頁
A14: 工 項 代 碼 | D14: 工 項 名 稱 | I14: 單 位 | K14: 工程用量 | M14: 單 價 | P14: 複 價 | Q14: 人 工 | T14: 機 具 | V14: 材 料 | W14: 雜 項
A15: 0127100004ZB01 | D15: 計量與計價，打鑿修補及復原(管線填封 隙封) | I15: 式 | P15: =IF(COUNT(K15,M15)=2,ROUND(K15*M15,0),"- -") -> - - | Q15: - - | T15: - - | V15: - - | W15: - -
A16: 0127100004ZB02 | D16: 計量與計價，工資 | I16: 式 | P16: =IF(COUNT(K16,M16)=2,ROUND(K16*M16,0),"-") -> - | Q16: - | T16: - | V16: - | W16: -
A17: 0127100004ZBICU01 | D17: 計量與計價，用電管理系統-智慧電表型 系統通訊閘道器 | I17: 式 | P17: =IF(COUNT(K17,M17)=2,ROUND(K17*M17,0),"- -") -> - - | Q17: - - | T17: - - | V17: - - | W17: - -
A18: 0127100004ZBICU02 | D18: 計量與計價，機房閘道器與IT資訊網路 點串接工程 | I18: 式 | P18: =IF(COUNT(K18,M18)=2,ROUND(K18*M18,0),"- -") -> - - | Q18: - - | T18: - - | V18: - - | W18: - -
A19: 0127100004ZBICU03 | D19: 計量與計價，軟體擴增費用 | I19: 式 | P19: =IF(COUNT(K19,M19)=2,ROUND(K19*M19,0),"-") -> - | Q19: - | T19: - | V19: - | W19: -
A20: 0127100004ZBICU04 | D20: 計量與計價，系統連接測試費 | I20: 式 | P20: =IF(COUNT(K20,M20)=2,ROUND(K20*M20,0),"-") -> - | Q20: - | T20: - | V20: - | W20: -
A21: 0127100004ZBICU05 | D21: 計量與計價，工程另料 | I21: 式 | P21: =IF(COUNT(K21,M21)=2,ROUND(K21*M21,0),"-") -> - | Q21: - | T21: - | V21: - | W21: -
A22: 0127100004ZBICU06 | D22: 計量與計價，工資 | I22: 式 | P22: =IF(COUNT(K22,M22)=2,ROUND(K22*M22,0),"-") -> - | Q22: - | T22: - | V22: - | W22: -
A23: 0127100004ZBICU07 | D23: 原水加壓系統 | I23: 台 | P23: =IF(COUNT(K23,M23)=2,ROUND(K23*M23,0),"-") -> - | Q23: - | T23: - | V23: - | W23: -
A24: 0127100004ZBICU08 | D24: 積層式過濾器 | I24: 套 | P24: =IF(COUNT(K24,M24)=2,ROUND(K24*M24,0),"-") -> - | Q24: - | T24: - | V24: - | W24: -
A25: 0127100004ZBICU09 | D25: 硬水軟化器 | I25: 套 | P25: =IF(COUNT(K25,M25)=2,ROUND(K25*M25,0),"-") -> - | Q25: - | T25: - | V25: - | W25: -
A26: 0127100004ZBICU10 | D26: 活性碳過濾器 | I26: 套 | P26: =IF(COUNT(K26,M26)=2,ROUND(K26*M26,0),"-") -> - | Q26: - | T26: - | V26: - | W26: -
A27: 0127100004ZBICU11 | D27: 精密過濾器 | I27: 組 | P27: =IF(COUNT(K27,M27)=2,ROUND(K27*M27,0),"-") -> - | Q27: - | T27: - | V27: - | W27: -
A28: 0127100004ZBICU12 | D28: 逆滲透淨水機 | I28: 套 | P28: =IF(COUNT(K28,M28)=2,ROUND(K28*M28,0),"-") -> - | Q28: - | T28: - | V28: - | W28: -
A29: 0127100004ZBICU13 | D29: 衛生級淨水貯桶 | I29: 個 | P29: =IF(COUNT(K29,M29)=2,ROUND(K29*M29,0),"-") -> - | Q29: - | T29: - | V29: - | W29: -
A30: 0127100004ZBICU14 | D30: 淨水供水設備 | I30: 台 | P30: =IF(COUNT(K30,M30)=2,ROUND(K30*M30,0),"-") -> - | Q30: - | T30: - | V30: - | W30: -
... A38: 0127100004ZBICU900 | D38: 計量與計價，原廠裝配工資 | I38: 式 | P38: =IF(COUNT(K38,M38)=2,ROUND(K38*M38,0),"-") -> - | Q38: - | T38: - | V38: - | W38: -
A39: 0127100004ZBICU901 | D39: 整合至院區既有Carrier監控系統(須連 接至Carrier ALC訊號) | I39: 式 | P39: =IF(COUNT(K39,M39)=2,ROUND(K39*M39,0),"- -") -> - - | Q39: - - | T39: - - | V39: - - | W39: - -
A40: 0127100004ZBRO01 | D40: 計量與計價，細菌化驗 | I40: 式 | P40: =IF(COUNT(K40,M40)=2,ROUND(K40*M40,0),"-") -> - | Q40: - | T40: - | V40: - | W40: -
A41: 0127100004ZBRO02 | D41: 計量與計價，內毒素化驗 | I41: 式 | P41: =IF(COUNT(K41,M41)=2,ROUND(K41*M41,0),"-") -> - | Q41: - | T41: - | V41: - | W41: -
A42: 0127100004ZBRO03 | D42: 計量與計價，試水試壓 | I42: 式 | P42: =IF(COUNT(K42,M42)=2,ROUND(K42*M42,0),"-") -> - | Q42: - | T42: - | V42: - | W42: -
A43: 0127100004ZBRO04 | D43: 計量與計價，消毒 | I43: 式 | P43: =IF(COUNT(K43,M43)=2,ROUND(K43*M43,0),"-") -> - | Q43: - | T43: - | V43: - | W43: -
A44: 0127100004ZBRO05 | D44: 計量與計價，零星材料 | I44: 式 | P44: =IF(COUNT(K44,M44)=2,ROUND(K44*M44,0),"-") -> - | Q44: - | T44: - | V44: - | W44: -
A45: 0127100004ZBRO06 | D45: 計量與計價，運雜費、運什費 | I45: 式 | P45: =IF(COUNT(K45,M45)=2,ROUND(K45*M45,0),"-") -> - | Q45: - | T45: - | V45: - | W45: -
A46: 0127100004ZBRO07 | D46: 計量與計價，工資 | I46: 式 | P46: =IF(COUNT(K46,M46)=2,ROUND(K46*M46,0),"-") -> - | Q46: - | T46: - | V46: - | W46: -
A47: 0127100004ZGA0403 | D47: 計量與計價，設備吊掛按裝及系統連結 測試 | I47: 式 | P47: =IF(COUNT(K47,M47)=2,ROUND(K47*M47,0),"- -") -> - - | Q47: - - | T47: - - | V47: - - | W47: - -
A48: 0127100004ZGF0501 | D48: 計量與計價，設備配管線配電工資 | I48: 式 | P48: =IF(COUNT(K48,M48)=2,ROUND(K48*M48,0),"-") -> - | Q48: - | T48: - | V48: - | W48: -
A49: 0127100004ZGH050 | D49: 1計A量與計價，袋進袋出過濾箱安裝工資 | I49: 式 | P49: =IF(COUNT(K49,M49)=2,ROUND(K49*M49,0),"-") -> - | Q49: - | T49: - | V49: - | W49: -
C51: 投標廠商： | G51: [印] | J51: 負責人： | L51: [印]
A54: 國立臺灣大學醫學院附設醫院
A56: 資源統計表[標單]
B58: 工 程 編 號 FB24033360_V6
B60: 工 程 名 稱 西址六東1樓(6E1)內科加護病房暨特殊病原科技照護示範中心整修工程
...
